{
  "smartbugs_completed": true,
  "analyzer_results": {
    "oyente": {
      "successfull_analysis": true,
      "errors": [],
      "vulnerability_findings": []
    },
    "slither": {
      "successfull_analysis": true,
      "errors": [
        "EXIT_CODE_2"
      ],
      "vulnerability_findings": [
        {
          "name": "external-function",
          "vulnerability_from_line": 6,
          "vulnerability_to_line": 11,
          "vulnerability_code": "    function withdrawBalance() {\n        uint amountToWithdraw = userBalances[msg.sender];\n        userBalances[msg.sender] = 0;\n\n        msg.sender.send(amountToWithdraw);",
          "message": "SendBack.withdrawBalance (mishandled.sol#6-11) should be declared external\n"
        },
        {
          "name": "solc-version",
          "vulnerability_from_line": 1,
          "vulnerability_to_line": null,
          "vulnerability_code": "pragma solidity ^0.4.0;",
          "message": "Detected issues with version pragma in mishandled.sol:\n\t- pragma solidity^0.4.0 (mishandled.sol#1): it allows old versions\n"
        }
      ]
    },
    "mythril-0.23.15": {
      "successfull_analysis": true,
      "errors": [],
      "vulnerability_findings": [
        {
          "name": "Unchecked return value from external call. (SWC 104)",
          "vulnerability_from_line": 10,
          "vulnerability_to_line": null,
          "vulnerability_code": "        msg.sender.send(amountToWithdraw);",
          "message": "The return value of a message call is not checked.\nExternal calls return a boolean value. If the callee halts with an exception, 'false' is returned and execution continues in the caller. The caller should check whether an exception happened and react accordingly to avoid unexpected behavior. For example it is often desirable to wrap external calls in require() so the transaction is reverted if the call fails.\nClassification: SWC-104"
        }
      ]
    }
  }
}